Workbook

Sheet Health Cleaned
A1: VisitDate | B1: PatientID | C1: Age | D1: Gender | E1: Diagnosis | F1: Treatment | G1: Doctor | H1: Cost
A2: 44903 | B2: P3653 | C2: 58 | D2: Male | E2: Cancer | F2: Therapy | G2: Dr.Lee | H2: 2804.9
A3: 44929 | B3: P3948 | C3: 19 | D3: Other | E3: Asthma | F3: Surgery | G3: Dr.Patel | H3: 3421.18
A4: 44660 | B4: P4013 | C4: 69 | D4: Male | E4: Hypertension | F4: Surgery | G4: Dr.Lee | H4: 3388.38
A5: 45018 | B5: P491 | C5: 50 | D5: Female | E5: Migraine | F5: Observation | G5: Dr.Lee | H5: 748.7
A6: 45258 | B6: P3223 | C6: 61 | D6: Female | E6: Diabetes | F6: Observation | G6: Dr.Patel | H6: 2817.94
A7: 45083 | B7: P457 | C7: 34 | D7: Male | E7: Unknown | F7: Surgery | G7: Dr.John | H7: 4719.84
A8: 44988 | B8: P4622 | C8: 20 | D8: Female | E8: Asthma | F8: Medication | G8: Dr.Lee | H8: 1079.46
A9: 44824 | B9: P3722 | C9: 68 | D9: Other | E9: Hypertension | F9: Observation | G9: Dr.John | H9: 2462.11
A10: 44669 | B10: P706 | C10: 51 | D10: Other | E10: Flu | F10: Surgery | G10: Dr.Lee | H10: 3013.89
A11: 45169 | B11: P184 | C11: 31 | D11: Female | E11: Covid-19 | F11: Observation | G11: Dr.Lee | H11: 2025.12
A12: 44894 | B12: P4448 | C12: 15 | D12: Other | E12: Hypertension | F12: Medication | G12: Dr.Smith | H12: 1727.97
A13: 45115 | B13: P866 | C13: 9 | D13: Other | E13: Hypertension | F13: Surgery | G13: Dr.Smith | H13: 925.55
... A5001: 44751 | B5001: P1688 | C5001: 17 | D5001: Male | E5001: Hypertension | F5001: Observation | G5001: Dr.Wong | H5001: 3112.16

Sheet Formulas
A1: Age | B1: Age Group | C1: PatientID | D1: Statistical Functions | E1: Treatment Types | F1: Standard Cost | G1: Cost With Tax | H1: Round | I1: Round Up | J1: Round Down | K1: Date Extract | L1: Age Range
A2: 58 | B2: =IF(A2<18,"CHILDREN",IF(A2<36,"YOUNG ADULTS",IF(A2<66,"ADULTS",IF(A2>65,"SENIORS")))) -> ADULTS | C2: P3653 | D2: =AVERAGE('Health Cleaned'!H2:H5001) -> 2488.1582 | E2: Therapy | F2: =VLOOKUP($E2,'Health Cleaned'!$F$2:$H$5001,3,FALSE) -> 2804.9 | G2: ='Health Cleaned'!$H2*1.1 -> 3085.39 | H2: =ROUND(G2,1) -> 3085.4 | I2: =ROUNDUP(G2,1) -> 3085.4 | J2: =ROUNDDOWN(G2,1) -> 3085.3 | K2: =TEXT('Health Cleaned'!A2,"mm-yy") -> 12-22 | L2: =IF(A2<13,"0-12",IF(A2<20,"13-19",IF(A2<35,"20-34",IF(A2<=50,"35-50",IF(A2<66,"51-65",IF(A2>65,"65-100")))))) -> 51-65
A3: 19 | B3: =IF(A3<18,"CHILDREN",IF(A3<36,"YOUNG ADULTS",IF(A3<66,"ADULTS",IF(A3>65,"SENIORS")))) -> YOUNG ADULTS | C3: P3948 | D3: =MIN('Health Cleaned'!H2:H5001) -> 20.23 | E3: Surgery | F3: =VLOOKUP($E3,'Health Cleaned'!$F$2:$H$5001,3,FALSE) -> 3421.18 | G3: ='Health Cleaned'!$H3*1.1 -> 3763.298 | H3: =ROUND(G3,1) -> 3763.3 | I3: =ROUNDUP(G3,1) -> 3763.3 | J3: =ROUNDDOWN(G3,1) -> 3763.2 | K3: =TEXT('Health Cleaned'!A3,"mm-yy") -> 01-23 | L3: =IF(A3<13,"0-12",IF(A3<20,"13-19",IF(A3<35,"20-34",IF(A3<=50,"35-50",IF(A3<66,"51-65",IF(A3>65,"65-100")))))) -> 13-19
A4: 69 | B4: =IF(A4<18,"CHILDREN",IF(A4<36,"YOUNG ADULTS",IF(A4<66,"ADULTS",IF(A4>65,"SENIORS")))) -> SENIORS | C4: P4013 | D4: =MAX('Health Cleaned'!H2:H5001) -> 4998.47 | E4: Observation | F4: =VLOOKUP($E4,'Health Cleaned'!$F$2:$H$5001,3,FALSE) -> 748.7 | G4: ='Health Cleaned'!$H4*1.1 -> 3727.218 | H4: =ROUND(G4,1) -> 3727.2 | I4: =ROUNDUP(G4,1) -> 3727.3 | J4: =ROUNDDOWN(G4,1) -> 3727.2 | K4: =TEXT('Health Cleaned'!A4,"mm-yy") -> 04-22 | L4: =IF(A4<13,"0-12",IF(A4<20,"13-19",IF(A4<35,"20-34",IF(A4<=50,"35-50",IF(A4<66,"51-65",IF(A4>65,"65-100")))))) -> 65-100
A5: 50 | B5: =IF(A5<18,"CHILDREN",IF(A5<36,"YOUNG ADULTS",IF(A5<66,"ADULTS",IF(A5>65,"SENIORS")))) -> ADULTS | C5: P491 | D5: =COUNTIF('Health Cleaned'!E2:E5001,"Diabetes") -> 643 | E5: Medication | F5: =VLOOKUP($E5,'Health Cleaned'!$F$2:$H$5001,3,FALSE) -> 1079.46 | G5: ='Health Cleaned'!$H5*1.1 -> 823.57 | H5: =ROUND(G5,1) -> 823.6 | I5: =ROUNDUP(G5,1) -> 823.6 | J5: =ROUNDDOWN(G5,1) -> 823.5 | K5: =TEXT('Health Cleaned'!A5,"mm-yy") -> 04-23 | L5: =IF(A5<13,"0-12",IF(A5<20,"13-19",IF(A5<35,"20-34",IF(A5<=50,"35-50",IF(A5<66,"51-65",IF(A5>65,"65-100")))))) -> 35-50
A6: 61 | B6: =IF(A6<18,"CHILDREN",IF(A6<36,"YOUNG ADULTS",IF(A6<66,"ADULTS",IF(A6>65,"SENIORS")))) -> ADULTS | C6: P3223 | G6: ='Health Cleaned'!$H6*1.1 -> 3099.734 | H6: =ROUND(G6,1) -> 3099.7 | I6: =ROUNDUP(G6,1) -> 3099.8 | J6: =ROUNDDOWN(G6,1) -> 3099.7 | K6: =TEXT('Health Cleaned'!A6,"mm-yy") -> 11-23 | L6: =IF(A6<13,"0-12",IF(A6<20,"13-19",IF(A6<35,"20-34",IF(A6<=50,"35-50",IF(A6<66,"51-65",IF(A6>65,"65-100")))))) -> 51-65
A7: 34 | B7: =IF(A7<18,"CHILDREN",IF(A7<36,"YOUNG ADULTS",IF(A7<66,"ADULTS",IF(A7>65,"SENIORS")))) -> YOUNG ADULTS | C7: P457 | G7: ='Health Cleaned'!$H7*1.1 -> 5191.824 | H7: =ROUND(G7,1) -> 5191.8 | I7: =ROUNDUP(G7,1) -> 5191.9 | J7: =ROUNDDOWN(G7,1) -> 5191.8 | K7: =TEXT('Health Cleaned'!A7,"mm-yy") -> 06-23 | L7: =IF(A7<13,"0-12",IF(A7<20,"13-19",IF(A7<35,"20-34",IF(A7<=50,"35-50",IF(A7<66,"51-65",IF(A7>65,"65-100")))))) -> 20-34
A8: 20 | B8: =IF(A8<18,"CHILDREN",IF(A8<36,"YOUNG ADULTS",IF(A8<66,"ADULTS",IF(A8>65,"SENIORS")))) -> YOUNG ADULTS | C8: P4622 | G8: ='Health Cleaned'!$H8*1.1 -> 1187.406 | H8: =ROUND(G8,1) -> 1187.4 | I8: =ROUNDUP(G8,1) -> 1187.5 | J8: =ROUNDDOWN(G8,1) -> 1187.4 | K8: =TEXT('Health Cleaned'!A8,"mm-yy") -> 03-23 | L8: =IF(A8<13,"0-12",IF(A8<20,"13-19",IF(A8<35,"20-34",IF(A8<=50,"35-50",IF(A8<66,"51-65",IF(A8>65,"65-100")))))) -> 20-34
A9: 68 | B9: =IF(A9<18,"CHILDREN",IF(A9<36,"YOUNG ADULTS",IF(A9<66,"ADULTS",IF(A9>65,"SENIORS")))) -> SENIORS | C9: P3722 | G9: ='Health Cleaned'!$H9*1.1 -> 2708.321 | H9: =ROUND(G9,1) -> 2708.3 | I9: =ROUNDUP(G9,1) -> 2708.4 | J9: =ROUNDDOWN(G9,1) -> 2708.3 | K9: =TEXT('Health Cleaned'!A9,"mm-yy") -> 09-22 | L9: =IF(A9<13,"0-12",IF(A9<20,"13-19",IF(A9<35,"20-34",IF(A9<=50,"35-50",IF(A9<66,"51-65",IF(A9>65,"65-100")))))) -> 65-100
A10: 51 | B10: =IF(A10<18,"CHILDREN",IF(A10<36,"YOUNG ADULTS",IF(A10<66,"ADULTS",IF(A10>65,"SENIORS")))) -> ADULTS | C10: P706 | G10: ='Health Cleaned'!$H10*1.1 -> 3315.279 | H10: =ROUND(G10,1) -> 3315.3 | I10: =ROUNDUP(G10,1) -> 3315.3 | J10: =ROUNDDOWN(G10,1) -> 3315.2 | K10: =TEXT('Health Cleaned'!A10,"mm-yy") -> 04-22 | L10: =IF(A10<13,"0-12",IF(A10<20,"13-19",IF(A10<35,"20-34",IF(A10<=50,"35-50",IF(A10<66,"51-65",IF(A10>65,"65-100")))))) -> 51-65
A11: 31 | B11: =IF(A11<18,"CHILDREN",IF(A11<36,"YOUNG ADULTS",IF(A11<66,"ADULTS",IF(A11>65,"SENIORS")))) -> YOUNG ADULTS | C11: P184 | G11: ='Health Cleaned'!$H11*1.1 -> 2227.632 | H11: =ROUND(G11,1) -> 2227.6 | I11: =ROUNDUP(G11,1) -> 2227.7 | J11: =ROUNDDOWN(G11,1) -> 2227.6 | K11: =TEXT('Health Cleaned'!A11,"mm-yy") -> 08-23 | L11: =IF(A11<13,"0-12",IF(A11<20,"13-19",IF(A11<35,"20-34",IF(A11<=50,"35-50",IF(A11<66,"51-65",IF(A11>65,"65-100")))))) -> 20-34
A12: 15 | B12: =IF(A12<18,"CHILDREN",IF(A12<36,"YOUNG ADULTS",IF(A12<66,"ADULTS",IF(A12>65,"SENIORS")))) -> CHILDREN | C12: P4448 | G12: ='Health Cleaned'!$H12*1.1 -> 1900.767 | H12: =ROUND(G12,1) -> 1900.8 | I12: =ROUNDUP(G12,1) -> 1900.8 | J12: =ROUNDDOWN(G12,1) -> 1900.7 | K12: =TEXT('Health Cleaned'!A12,"mm-yy") -> 11-22 | L12: =IF(A12<13,"0-12",IF(A12<20,"13-19",IF(A12<35,"20-34",IF(A12<=50,"35-50",IF(A12<66,"51-65",IF(A12>65,"65-100")))))) -> 13-19
A13: 9 | B13: =IF(A13<18,"CHILDREN",IF(A13<36,"YOUNG ADULTS",IF(A13<66,"ADULTS",IF(A13>65,"SENIORS")))) -> CHILDREN | C13: P866 | G13: ='Health Cleaned'!$H13*1.1 -> 1018.105 | H13: =ROUND(G13,1) -> 1018.1 | I13: =ROUNDUP(G13,1) -> 1018.2 | J13: =ROUNDDOWN(G13,1) -> 1018.1 | K13: =TEXT('Health Cleaned'!A13,"mm-yy") -> 07-23 | L13: =IF(A13<13,"0-12",IF(A13<20,"13-19",IF(A13<35,"20-34",IF(A13<=50,"35-50",IF(A13<66,"51-65",IF(A13>65,"65-100")))))) -> 0-12
A14: 9 | B14: =IF(A14<18,"CHILDREN",IF(A14<36,"YOUNG ADULTS",IF(A14<66,"ADULTS",IF(A14>65,"SENIORS")))) -> CHILDREN | C14: P4827 | G14: ='Health Cleaned'!$H14*1.1 -> 4154.128 | H14: =ROUND(G14,1) -> 4154.1 | I14: =ROUNDUP(G14,1) -> 4154.2 | J14: =ROUNDDOWN(G14,1) -> 4154.1 | K14: =TEXT('Health Cleaned'!A14,"mm-yy") -> 08-22 | L14: =IF(A14<13,"0-12",IF(A14<20,"13-19",IF(A14<35,"20-34",IF(A14<=50,"35-50",IF(A14<66,"51-65",IF(A14>65,"65-100")))))) -> 0-12
A15: 49 | B15: =IF(A15<18,"CHILDREN",IF(A15<36,"YOUNG ADULTS",IF(A15<66,"ADULTS",IF(A15>65,"SENIORS")))) -> ADULTS | C15: P1911 | G15: ='Health Cleaned'!$H15*1.1 -> 1292.225 | H15: =ROUND(G15,1) -> 1292.2 | I15: =ROUNDUP(G15,1) -> 1292.3 | J15: =ROUNDDOWN(G15,1) -> 1292.2 | K15: =TEXT('Health Cleaned'!A15,"mm-yy") -> 11-23 | L15: =IF(A15<13,"0-12",IF(A15<20,"13-19",IF(A15<35,"20-34",IF(A15<=50,"35-50",IF(A15<66,"51-65",IF(A15>65,"65-100")))))) -> 35-50
A16: 23 | B16: =IF(A16<18,"CHILDREN",IF(A16<36,"YOUNG ADULTS",IF(A16<66,"ADULTS",IF(A16>65,"SENIORS")))) -> YOUNG ADULTS | C16: P4079 | G16: ='Health Cleaned'!$H16*1.1 -> 1644.566 | H16: =ROUND(G16,1) -> 1644.6 | I16: =ROUNDUP(G16,1) -> 1644.6 | J16: =ROUNDDOWN(G16,1) -> 1644.5 | K16: =TEXT('Health Cleaned'!A16,"mm-yy") -> 09-23 | L16: =IF(A16<13,"0-12",IF(A16<20,"13-19",IF(A16<35,"20-34",IF(A16<=50,"35-50",IF(A16<66,"51-65",IF(A16>65,"65-100")))))) -> 20-34
A17: 21 | B17: =IF(A17<18,"CHILDREN",IF(A17<36,"YOUNG ADULTS",IF(A17<66,"ADULTS",IF(A17>65,"SENIORS")))) -> YOUNG ADULTS | C17: P509 | G17: ='Health Cleaned'!$H17*1.1 -> 4058.593 | H17: =ROUND(G17,1) -> 4058.6 | I17: =ROUNDUP(G17,1) -> 4058.6 | J17: =ROUNDDOWN(G17,1) -> 4058.5 | K17: =TEXT('Health Cleaned'!A17,"mm-yy") -> 06-23 | L17: =IF(A17<13,"0-12",IF(A17<20,"13-19",IF(A17<35,"20-34",IF(A17<=50,"35-50",IF(A17<66,"51-65",IF(A17>65,"65-100")))))) -> 20-34
... A5001: 17 | B5001: =IF(A5001<18,"CHILDREN",IF(A5001<36,"YOUNG ADULTS",IF(A5001<66,"ADULTS",IF(A5001>65,"SENIORS")))) -> CHILDREN | C5001: P1688 | G5001: ='Health Cleaned'!$H5001*1.1 -> 3423.376 | H5001: =ROUND(G5001,1) -> 3423.4 | I5001: =ROUNDUP(G5001,1) -> 3423.4 | J5001: =ROUNDDOWN(G5001,1) -> 3423.3 | K5001: =TEXT('Health Cleaned'!A5001,"mm-yy") -> 07-22 | L5001: =IF(A5001<13,"0-12",IF(A5001<20,"13-19",IF(A5001<35,"20-34",IF(A5001<=50,"35-50",IF(A5001<66,"51-65",IF(A5001>65,"65-100")))))) -> 13-19

Sheet Analysis
A1: 1 | D1: 2
A2: Row Labels | B2: Sum of Cost | E2: Column Labels
A3: Dr.John | B3: 2318307.2 | E3: Female | F3: Male | G3: Other | H3: Grand Total
A4: Dr.Lee | B4: 2473815.5 | D4: Count of PatientID | E4: 1653 | F4: 1653 | G4: 1694 | H4: 5000
A5: Dr.Patel | B5: 2435514.4
A6: Dr.Smith | B6: 2327614.6
A7: Dr.Wong | B7: 2492231.3
A8: Unassigned | B8: 393307.97
A9: Grand Total | B9: 12440791
G10: {=Maxi} -> #NAME?
A11: 3 | D11: 4
A12: Row Labels | B12: Average of Cost | D12: Row Labels | E12: Count of PatientID
A13: Asthma | B13: 2441.1555 | D13: ADULTS | E13: 0.3032
A14: Cancer | B14: 2527.9798 | D14: CHILDREN | E14: 0.1764
A15: Covid-19 | B15: 2486.5416 | D15: SENIOR ADULTS | E15: 0.3458
A16: Diabetes | B16: 2434.9329 | D16: YOUNG ALDULTS | E16: 0.1746
A17: Flu | B17: 2538.3202 | D17: Grand Total | E17: 1
A18: Hypertension | B18: 2494.0736
A19: Migraine | B19: 2507.9048
A20: Unknown | B20: 2457.8956
A21: Grand Total | B21: 2488.1582
A24: 5
A25: Row Labels | B25: Count of PatientID | D25: 5
A26: Female | B26: 0.3306
A27: Male | B27: 0.3306
A28: Other | B28: 0.3388
A29: Grand Total | B29: 1
A39: 6
A40: Row Labels | B40: Sum of Cost
A41: Asthma | B41: 1569663
A42: Cancer | B42: 1724082.2
A43: Covid-19 | B43: 1653550.2
A44: Diabetes | B44: 1565661.9
A45: Flu | B45: 1619448.3
A46: Hypertension | B46: 1646088.6
A47: Migraine | B47: 1745501.8
A48: Unknown | B48: 916795.05
A49: Grand Total | B49: 12440791

Sheet Health_Dirty
A1: VisitDate | B1: PatientID | C1: Age | D1: Gender | E1: Diagnosis | F1: Treatment | G1: Doctor | H1: Cost | I1: Age Range
A2: 44785 | B2: P3653 | C2: 58 | D2: Male | E2: Cancer | F2: Therapy | G2: Dr. Lee | H2: 2804.9
A3: 44986 | B3: P3948 | C3: 19 | D3: Other | E3: Asthma | F3: Surgery | G3: Dr. Patel | H3: 3421.18
A4: 44808 | B4: P4013 | C4: 69 | D4: Male | E4: Hypertension | F4: Surgery | G4: Dr. Lee | H4: 3388.38
A5: 44961 | B5: P491 | C5: 50 | D5: Female | E5: Migraine | F5: Observation | G5: Dr. Lee | H5: 748.7
A6: 28/11/2023 | B6: P3223 | C6: 61 | D6: Female | E6: Diabetes | F6: Observation | G6: Dr. Patel | H6: 2817.94
A7: 45083 | B7: P457 | C7: 34 | D7: Male | F7: Surgery | G7: Dr. John | H7: 4719.84
A8: 44988 | B8: P4622 | C8: 20 | D8: Female | E8: Asthma | F8: Medication | G8: Dr. Lee | H8: 1079.46
A9: 20/09/2022 | B9: P3722 | C9: 68 | D9: Other | E9: Hypertension | F9: Observation | G9: Dr. John | H9: 2462.11
A10: 18/04/2022 | B10: P706 | C10: 51 | D10: Other | E10: Flu | F10: Surgery | G10: Dr. Lee | H10: 3013.89
A11: 31/08/2023 | B11: P184 | C11: 31 | D11: Female | E11: Covid-19 | F11: Observation | G11: Dr. Lee | H11: 2025.12
A12: 29/11/2022 | B12: P4448 | C12: 15 | D12: Other | E12: Hypertension | F12: Medication | G12: Dr. Smith | H12: 1727.97
A13: 45145 | B13: P866 | C13: 9 | D13: Other | E13: Hypertension | F13: Surgery | G13: Dr. Smith | H13: 925.55
A14: 44781 | B14: P4827 | C14: 9 | D14: Female | E14: Covid-19 | F14: Surgery | G14: Dr. Wong | H14: 3776.48
A15: 45057 | B15: P1911 | C15: 49 | D15: Other | E15: Asthma | F15: Observation | G15: Dr. Smith | H15: 1174.75
A16: 21/09/2023 | B16: P4079 | C16: 23 | D16: Other | E16: Asthma | F16: Medication | G16: Dr. Patel | H16: 1495.06
A17: 16/06/2023 | B17: P509 | C17: 21 | D17: Male | E17: Migraine | F17: Therapy | G17: Dr. Wong | H17: 3689.63
A18: 18/12/2023 | B18: P1764 | C18: 17 | D18: Male | E18: Flu | F18: Medication | G18: Dr. Lee | H18: 3663.43
A19: 26/03/2022 | B19: P904 | C19: 25 | D19: Other | E19: Flu | F19: Medication | G19: Dr. Patel | H19: 3218.47
A20: 45171 | B20: P273 | C20: 18 | D20: Female | E20: Flu | F20: Medication | G20: Dr. Lee | H20: 2984.95
A21: 14/04/2022 | B21: P123 | C21: 35 | D21: Female | E21: Migraine | F21: Observation | G21: Dr. Lee | H21: 4236.83
A22: 45018 | B22: P951 | C22: 63 | D22: Male | E22: Cancer | F22: Observation | G22: Dr. Patel | H22: 581.22
A23: 27/12/2022 | B23: P1658 | C23: 44 | D23: Female | E23: Flu | F23: Medication | G23: Dr. John | H23: 4277.79
A24: 13/06/2022 | B24: P2741 | C24: 52 | D24: Male | E24: Migraine | F24: Surgery | G24: Dr. Wong | H24: 630.17
A25: 45025 | B25: P2807 | C25: 33 | D25: Female | E25: Cancer | F25: Medication | G25: Dr. Wong | H25: 1755.98
A26: 45232 | B26: P4793 | C26: 79 | D26: Other | E26: Flu | F26: Therapy | G26: Dr. Wong | H26: 2287.68
A27: 23/09/2022 | B27: P259 | C27: 26 | D27: Female | E27: Covid-19 | F27: Medication | G27: Dr. Wong | H27: 2025.75
A28: 14/12/2022 | B28: P4413 | C28: 99 | D28: Male | E28: Covid-19 | F28: Surgery | G28: Dr. Wong | H28: 3416.38
A29: 25/07/2023 | B29: P4790 | C29: 53 | D29: Other | E29: Cancer | F29: Medication | G29: Dr. John | H29: 4149.75
A30: 29/07/2022 | B30: P1787 | C30: 54 | D30: Female | E30: Asthma | F30: Observation | G30: Dr. Patel | H30: 3123.31
A31: 25/01/2022 | B31: P4336 | C31: 34 | D31: Female | E31: Diabetes | F31: Medication | G31: Dr. Lee | H31: 2471.39
A32: 25/04/2023 | B32: P1716 | C32: 29 | D32: Male | E32: Diabetes | F32: Surgery | G32: Dr. Patel | H32: 2124.15
A33: 45272 | B33: P1617 | C33: 39 | D33: Male | E33: Cancer | F33: Observation | G33: Dr. John | H33: 1312.71
A34: 45271 | B34: P1253 | C34: 39 | D34: Female | E34: Covid-19 | F34: Medication | G34: Dr. Patel | H34: 4686.86
A35: 44779 | B35: P4575 | C35: 37 | D35: Male | E35: Diabetes | F35: Medication | G35: Dr. Smith | H35: 3811.95
A36: 44845 | B36: P4050 | C36: 23 | D36: Male | E36: Covid-19 | F36: Surgery | G36: Dr. Wong | H36: 1104.21
A37: 44836 | B37: P1457 | C37: 50 | D37: Female | E37: Hypertension | F37: Therapy | G37: Dr. Patel | H37: 2400.57
A38: 44780 | B38: P1828 | C38: 27 | D38: Female | E38: Covid-19 | F38: Therapy | G38: Dr. Wong | H38: 1913.22
A39: 14/04/2023 | B39: P4736 | C39: 35 | D39: Female | E39: Hypertension | F39: Surgery | G39: Dr. Smith | H39: 4275.91
A40: 15/12/2022 | B40: P4630 | C40: 30 | D40: Male | E40: Asthma | F40: Therapy | H40: 2345.22
...
